---
title: |
    PyQT5 一个偶发性段错误的Debug
category: 学习记录
author: 赵明心
excerpt: |
    PyQt5 上发生的一个Bug记录
use_math: true
#feature_text: |
  ## The Pot Still
#  The modern pot still is a descendant of the alembic, an earlier distillation device
#feature_image: "https://unsplash.it/1200/400?image=1048"
#image: "https://unsplash.it/1200/400?image=1048"
---

#### 问题

在运行用PyQT5编写的测试用GUI界面时偶发一个段错误(Segmentation Fault)，导致操作系统(Ubuntu 18.04)发出SIGSEGV 11信号杀死进程。在Python中段错误通常发生在进行外部调用的时候，python解释器本身极少存在能引发段错误的bug，而且这个错误主要来自于不当的内存引用导致的内存泄漏、越界访问等问题。

起初怀疑是后台调用的若干C线程发生错误，因为在编写这个GUI的时候使用了线程池，可能没有很好的管理线程安全性问题导致的内存错误，但没有办法进行明确定位。

在PyCharm IDE内无法追踪到错误位置，PyQT5是C++版QT5的Python封装，不能直接在python环境下debug。

#### 解决方案：

借助gdb工具进行debug，相当于以C/C++的方式debug python解释器，然后再用python解释器来运行GUI脚本文件，这样可以在发生错误的时候用gdb的backtrace定位C/C++接口函数的错误位置。

最后发现在Qt5的C/C++接口函数：
- recalcAdvances(QGlyphLayout*, QFlags<QFontEngine::ShaperFlag>) const ()
- QFontEngineFT::loadGlyphSet(QTransform const&) ()

出现错误。同时，若干次错误都发生在同一个动态链接库libQt5XcbQpa.so.5。

现在仅仅是定位到这个链接库中的错误，下一步继续定位具体引发错误的原因。